<robot name="robot_arm">
    <link name="base_link">
        <visual>
            <orgin xyz="0 0 0.0255" rpy="0 0 0"/>
            <geometry>
                <cylinder length="0.050" radius="0.089"/>
            </geometry>
        </visual>
    </link>

    <link name="base_rot">
        <visual>
            <geometry>
                <box size="0.05 0.05 0.056" />
            </geometry>
        </visual>
    </link>

    <joint name="base_joint" type="revolute">
        <parent link="base_link" />
        <child link="base_rot" />
        <orgin xyz="0 0 0.072" rpy="0 0 0"/>
        <axis xyz="0 0 -1" />
    </joint>
    
</robot>
